Workbook

Sheet ENERO
A1: FECHA DE EMISION DEL COMPROBANTE DE PAGO O DOCUMENTO | B1: FECHA DE VENCIMIENTO O FECHA DE PAGO | C1: COMPROBANTE DE PAGO O DOCUMENTO | F1: N° COMPROBANTE PAGO | G1: INFORMACION PROVEEDOR | J1: ADQUISICIONES GRAVADAS DESTINADAS A OPERACIONES GRAVADAS Y/O EXPORTACION | L1: ADQUISICIONES GRAVADAS DESTINADAS A OPERACIONES GRAVADAS Y/O DE EXPORTACION Y A OPERACIONES NO GRAVADAS | N1: ADQUISICIONES GRAVADAS DESTINADAS A OPERACIONES NO GRAVADAS | P1: VALOR DE LAS ADQUISICIONES NO GRAVADAS | Q1: ISC | R1: OTROS TRIBUTOS Y CARGOS | S1: IMPORTE TOTAL | T1: N° COMPROBANTE DE PAGO EMITIDO POR SUJETO NO DOMICILIADO | U1: CONSTANCIA DE DEPOSITO DE DETRACCION | W1: TIPO DE CAMBIO | X1: REFERENCIA DEL COMPROBANTE DE PAGO O DOCUMENTO ORIGINAL QUE SE MODIFICA | AB1: MONEDA | AC1: EQUIVALENTE EN DOLARES AMERICANOS | AD1: FECHA VENCIMIENTO | AE1: CONDICION CONTADO/CREDITO | AF1: CUENTA CONTABLE BASE IMPONIBLE | AG1: CUENTA CONTABLE OTROS TRIBUTOS Y CARGOS | AH1: CUENTA CONTABLE TOTAL | AI1: CODIGO CENTRO DE COSTOS | AJ1: CODIGO CENTRO DE COSTOS 2 | AK1: REGIMEN ESPECIAL | AL1: PORCENTAJE REGIMEN ESPECIAL | AM1: IMPORTE REGIMEN ESPECIAL | AN1: SERIE DOCUMENTO REGIMEN ESPECIAL | AO1: NUMERO DOCUMENTO REGIMEN ESPECIAL | AP1: FECHA DOCUMENTO REGIMEN ESPECIAL | AQ1: CODIGO PRESUPUESTO | AR1: PORCENTAJE I.G.V. | AS1: GLOSA | AT1: CONDICIÓN DE PERCEPCIÓN | AU1: IMPORTE RÉGIMEN ESPECIAL | AV1: CLASIFICACIÓN DE BIENES Y SERVICIOS ADQUIRIDOS
G2: DOCUMENTO IDENTIDAD | I2: APELLIDOS Y NOMBRES, DENOMINACION O RAZON SOCIAL
D3: SERIE/CODIGO ADUANA | E3: AÑO EMISION DUA O DSI | G3: TIPO | H3: NUMERO | J3: BASE IMPONIBLE | K3: IGV | L3: BASE IMPONIBLE | M3: IGV | N3: BASE IMPONIBLE | O3: IGV | U3: NUMERO | V3: FECHA EMISION | X3: FECHA | Y3: TIPO | Z3: SERIE | AA3: N° COMPROBANTE PAGO O DOCUMENTO
A4: 46021 | C4: 14 | D4: 00S898 | F4: 85617271 | G4: 6 | H4: 20129646099 | I4: =IF(H4="","",VLOOKUP(H4,ENTIDAD!$B$2:$C$613,2,0)) -> ELECTROCENTRO S.A. | N4: =(S4-P4)/1.18 -> 0 | O4: =N4*0.18 -> 0 | P4: 604.4 | S4: 604.4 | AB4: S | AD4: 46037 | AE4: CRE | AF4: 6361095 | AH4: 4212 | AR4: 18 | AS4: POR EL SERVICIO DE ENERGIA ELECTRICA
A5: 46022 | C5: 14 | D5: 000060 | F5: 1046898 | G5: 6 | H5: 20121876290 | I5: =IF(H5="","",VLOOKUP(H5,ENTIDAD!$B$2:$C$613,2,0)) -> ENT.PREST.SERV.SANEAM.SELVA CENTRAL S.A | N5: =(S5-P5)/1.18 -> 0 | O5: =N5*0.18 -> 0 | P5: 45.8 | S5: 45.8 | AB5: S | AD5: 46053 | AE5: CRE | AF5: 6363095 | AH5: 4212 | AR5: 18 | AS5: POR EL SERVICIO DE AGUA POTABLE
A6: 46025 | C6: 01 | D6: 00F001 | F6: 116472 | G6: 6 | H6: 20568499043 | I6: =IF(H6="","",VLOOKUP(H6,ENTIDAD!$B$2:$C$613,2,0)) -> SURTIDORES SAN MIGUEL E.I.R.L. | N6: =(S6-P6)/1.18 -> 0 | O6: =N6*0.18 -> 0 | P6: 100.02 | S6: 100.02 | AB6: S | AD6: 46025 | AE6: CON | AF6: 656009401 | AH6: 4212 | AR6: 18 | AS6: POR LA COMPRA DE COMBUSTIBLE
A7: 46026 | C7: 01 | D7: 00E001 | F7: 133 | G7: 6 | H7: 10447422951 | I7: =IF(H7="","",VLOOKUP(H7,ENTIDAD!$B$2:$C$613,2,0)) -> ZEGARRA AZAÑERO JORGE KEY | N7: =(S7-P7)/1.18 -> 0 | O7: =N7*0.18 -> 0 | P7: 450 | S7: 450 | AB7: S | AD7: 46026 | AE7: CRE | AF7: 6599094 | AH7: 4212 | AR7: 18 | AS7: SOPORTE TECNICO
A8: 46027 | C8: 01 | D8: 00F001 | F8: 116533 | G8: 6 | H8: 20568499043 | I8: =IF(H8="","",VLOOKUP(H8,ENTIDAD!$B$2:$C$613,2,0)) -> SURTIDORES SAN MIGUEL E.I.R.L. | N8: =(S8-P8)/1.18 -> 0 | O8: =N8*0.18 -> 0 | P8: 100.02 | S8: 100.02 | AB8: S | AD8: 46027 | AE8: CON | AF8: 656009401 | AH8: 4212 | AR8: 18 | AS8: POR LA COMPRA DE COMBUSTIBLE
A9: 46027 | C9: 01 | D9: 00E001 | F9: 144 | G9: 6 | H9: 10447422951 | I9: =IF(H9="","",VLOOKUP(H9,ENTIDAD!$B$2:$C$613,2,0)) -> ZEGARRA AZAÑERO JORGE KEY | N9: =(S9-P9)/1.18 -> 0 | O9: =N9*0.18 -> 0 | P9: 1000 | S9: 1000 | AB9: S | AD9: 46027 | AE9: CRE | AF9: 6599094 | AH9: 4212 | AR9: 18 | AS9: ACTUALIZACION DEL MODULO DE CREDITOS
A10: 46027 | C10: 01 | D10: 00E001 | F10: 5947 | G10: 6 | H10: 20602783341 | I10: =IF(H10="","",VLOOKUP(H10,ENTIDAD!$B$2:$C$613,2,0)) -> CODISSER VRAEM E.I.R.L. | N10: =(S10-P10)/1.18 -> 0 | O10: =N10*0.18 -> 0 | P10: 16 | S10: 16 | AB10: S | AD10: 46027 | AE10: CON | AF10: 6250095 | AH10: 4212 | AR10: 18 | AS10: POR LA COMPRA DE AGUA MESA
A11: 46027 | C11: 01 | D11: 00FE01 | F11: 2675796 | G11: 6 | H11: 20100047218 | I11: =IF(H11="","",VLOOKUP(H11,ENTIDAD!$B$2:$C$613,2,0)) -> BANCO DE CREDITO DEL PERU | N11: =(S11-P11)/1.18 -> 0 | O11: =N11*0.18 -> 0 | P11: 117.88 | S11: =W11*AC11 -> 117.88 | W11: 3.368 | AB11: D | AC11: 35 | AD11: 46027 | AE11: CRE | AF11: 6391094 | AH11: 4212 | AR11: 18 | AS11: POR LA COMISION BANCARIA
A12: 46027 | C12: 01 | D12: 00FC04 | F12: 4694311 | G12: 6 | H12: 20100130204 | I12: =IF(H12="","",VLOOKUP(H12,ENTIDAD!$B$2:$C$613,2,0)) -> BANCO BBVA PERU | N12: =(S12-P12)/1.18 -> 0 | O12: =N12*0.18 -> 0 | P12: 40 | S12: 40 | AB12: S | AD12: 46027 | AE12: CRE | AF12: 6391094 | AH12: 4212 | AR12: 18 | AS12: POR LA COMISION BANCARIA
A13: 46027 | C13: 01 | D13: 00FB25 | F13: 25369180 | G13: 6 | H13: 20100130204 | I13: =IF(H13="","",VLOOKUP(H13,ENTIDAD!$B$2:$C$613,2,0)) -> BANCO BBVA PERU | N13: =(S13-P13)/1.18 -> 0 | O13: =N13*0.18 -> 0 | P13: 10 | S13: 10 | AB13: S | AD13: 46027 | AE13: CRE | AF13: 6391094 | AH13: 4212 | AR13: 18 | AS13: POR LA COMISION BANCARIA
A14: 46028 | C14: 01 | D14: 00FI01 | F14: 18054814 | G14: 6 | H14: 20100047218 | I14: =IF(H14="","",VLOOKUP(H14,ENTIDAD!$B$2:$C$613,2,0)) -> BANCO DE CREDITO DEL PERU | N14: =(S14-P14)/1.18 -> 0 | O14: =N14*0.18 -> 0 | P14: 914.5 | R14: 0 | S14: 914.5 | AB14: S | AD14: 46028 | AE14: CRE | AF14: 6391094 | AH14: 4212 | AR14: 18 | AS14: POR LA COMISION BANCARIA
A15: 46028 | C15: 01 | D15: 00E001 | F15: 1525 | G15: 6 | H15: 20611910887 | I15: =IF(H15="","",VLOOKUP(H15,ENTIDAD!$B$2:$C$613,2,0)) -> CORPORACION UNIVERSAL M&F SOCIEDAD ANONIMA CERRADA | N15: =(S15-P15)/1.18 -> 0 | O15: =N15*0.18 -> 0 | P15: 170 | R15: 0 | S15: 170 | AB15: S | AD15: 46028 | AE15: CRE | AF15: 656009506 | AH15: 4212 | AR15: 18 | AS15: POR LA IMPRESIÓN DE DE FORMATOS
A16: 46028 | C16: 01 | D16: 00E001 | F16: 60 | G16: 6 | H16: 10733619207 | I16: =IF(H16="","",VLOOKUP(H16,ENTIDAD!$B$2:$C$613,2,0)) -> UNTIVEROS SOLDEVILLA MIGUEL COLIN | N16: =(S16-P16)/1.18 -> 0 | O16: =N16*0.18 -> 0 | P16: 5500 | R16: 0 | S16: 5500 | AB16: S | AD16: 46028 | AE16: CRE | AH16: 4212 | AR16: 18 | AS16: LETREROS CON LUCES LED
A17: 46028 | C17: 01 | D17: 00E001 | F17: 81 | G17: 6 | H17: 20568685424 | I17: =IF(H17="","",VLOOKUP(H17,ENTIDAD!$B$2:$C$613,2,0)) -> VISUAL´S MERCHANDISING S.A.C. | N17: =(S17-P17)/1.18 -> 0 | O17: =N17*0.18 -> 0 | P17: 1000 | S17: 1000 | AB17: S | AD17: 46028 | AE17: CRE | AF17: 6371095 | AH17: 4212 | AR17: 18 | AS17: POR EL SERVICIO DE PUBLICIDAD
A18: 46029 | C18: 01 | D18: 00E001 | F18: 182 | G18: 6 | H18: 10207070098 | I18: =IF(H18="","",VLOOKUP(H18,ENTIDAD!$B$2:$C$613,2,0)) -> ROJAS FLORES ELISEO MAXIMO | N18: =(S18-P18)/1.18 -> 0 | O18: =N18*0.18 -> 0 | P18: 2000 | R18: 0 | S18: 2000 | AB18: S | AD18: 46029 | AE18: CRE | AF18: 6011020 | AH18: 4212 | AR18: 18 | AS18: POR LA COMPRA DE PARABRIZAS
A19: 46029 | C19: 01 | D19: 00FV13 | F19: 1272573 | G19: 6 | H19: 20100047218 | I19: =IF(H19="","",VLOOKUP(H19,ENTIDAD!$B$2:$C$613,2,0)) -> BANCO DE CREDITO DEL PERU | N19: =(S19-P19)/1.18 -> 0 | O19: =N19*0.18 -> 0 | P19: 154.5 | S19: 154.5 | AB19: S | AD19: 46029 | AE19: CRE | AF19: 6391094 | AH19: 4212 | AR19: 18 | AS19: POR LA COMISION BANCARIA
A20: 46030 | C20: 01 | D20: 00E001 | F20: 115 | G20: 6 | H20: 20604194211 | I20: =IF(H20="","",VLOOKUP(H20,ENTIDAD!$B$2:$C$613,2,0)) -> MULTISERVICIOS COMPANY SELVA SOCIEDAD ANÓNIMA CERRADA | N20: =(S20-P20)/1.18 -> 0 | O20: =N20*0.18 -> 0 | P20: 1028.5 | R20: 0 | S20: 1028.5 | AB20: S | AD20: 46030 | AE20: CRE | AF20: 6314095 | AH20: 4212 | AR20: 18 | AS20: POR CONSUMO DE ALIMENTOS
A21: 46031 | C21: 01 | D21: 00F005 | F21: 16248 | G21: 6 | H21: 20493508645 | I21: =IF(H21="","",VLOOKUP(H21,ENTIDAD!$B$2:$C$613,2,0)) -> HONDA SELVA DEL PERU S.A. | N21: =(S21-P21)/1.18 -> -0.00088135593 | O21: =N21*0.18 -> -0.00015864407 | P21: 34926.06 | S21: =W21*AC21 -> 34926.059 | W21: 3.368 | AB21: D | AC21: 10369.97 | AD21: 46062 | AE21: CRE | AF21: 6011021 | AH21: 4212 | AR21: 18 | AS21: EXISTENCIAS POR RECIBIR
A22: 46031 | C22: 07 | D22: 00FN11 | F22: 75 | G22: 6 | H22: 20600014529 | I22: =IF(H22="","",VLOOKUP(H22,ENTIDAD!$B$2:$C$613,2,0)) -> OSPINA FERRETERA S.R.L. | N22: =(S22-P22)/1.18 -> -279.66102 | O22: =N22*0.18 -> -50.338983 | S22: -330 | X22: 46008 | Y22: 01 | Z22: F011 | AA22: 4319 | AB22: S | AD22: 46031 | AE22: CRE | AF22: 6560095 | AH22: 4212 | AR22: 18 | AS22: ANULACION DE LA OPERACIÓN
A23: 46031 | C23: 07 | D23: 00E001 | F23: 3 | G23: 6 | H23: 10207070098 | I23: =IF(H23="","",VLOOKUP(H23,ENTIDAD!$B$2:$C$613,2,0)) -> ROJAS FLORES ELISEO MAXIMO | N23: =(S23-P23)/1.18 -> 0 | O23: =N23*0.18 -> 0 | P23: -2000 | S23: -2000 | X23: 46029 | Y23: 01 | Z23: E001 | AA23: 182 | AB23: S | AD23: 46031 | AE23: CRE | AF23: 6011020 | AH23: 4212 | AR23: 18 | AS23: ANULACION DE LA OPERACIÓN
A24: 46031 | C24: 01 | D24: 00F011 | F24: 4664 | G24: 6 | H24: 20600014529 | I24: =IF(H24="","",VLOOKUP(H24,ENTIDAD!$B$2:$C$613,2,0)) -> OSPINA FERRETERA S.R.L. | N24: =(S24-P24)/1.18 -> 279.66102 | O24: =N24*0.18 -> 50.338983 | P24: 0 | S24: 330 | AB24: S | AD24: 46031 | AE24: CRE | AF24: 6560095 | AH24: 4212 | AR24: 18 | AS24: CANDADO DE BRONCE
A25: 46034 | C25: 01 | D25: 00E001 | F25: 1319 | G25: 6 | H25: 20573301715 | I25: =IF(H25="","",VLOOKUP(H25,ENTIDAD!$B$2:$C$613,2,0)) -> CASCOS FORRADOS PERICO S.A.C | N25: =(S25-P25)/1.18 -> 0 | O25: =N25*0.18 -> 0 | P25: 3600 | R25: 0 | S25: 3600 | AB25: S | AD25: 46034 | AE25: CRE | AF25: 6031025 | AH25: 4212 | AR25: 18 | AS25: POR LA COMPRA DE CASCOS
A26: 46034 | C26: 01 | D26: 00F341 | F26: 10045 | G26: 6 | H26: 20512528458 | I26: =IF(H26="","",VLOOKUP(H26,ENTIDAD!$B$2:$C$613,2,0)) -> SHALOM EMPRESARIAL S.A.C. | N26: =(S26-P26)/1.18 -> 86.440678 | O26: =N26*0.18 -> 15.559322 | R26: 0 | S26: 102 | AB26: S | AD26: 46034 | AE26: CRE | AF26: 6311195 | AH26: 4212 | AR26: 18 | AS26: POR EL SERVICIO DE TRANSPORTE
A27: 46034 | C27: 01 | D27: 00F001 | F27: 12551 | G27: 6 | H27: 10209907327 | I27: =IF(H27="","",VLOOKUP(H27,ENTIDAD!$B$2:$C$613,2,0)) -> TORPOCO,MAYTA,HECTOR,ALFONSO | N27: =(S27-P27)/1.18 -> 0 | O27: =N27*0.18 -> 0 | P27: 10 | R27: 0 | S27: 10 | AB27: S | AD27: 46034 | AE27: CON | AF27: 656009501 | AH27: 4212 | AR27: 18 | AS27: POR LA COMPRA DE COMBUSTIBLE
A28: 46035 | C28: 01 | D28: 00E001 | F28: 1106 | G28: 6 | H28: 20607824666 | I28: =IF(H28="","",VLOOKUP(H28,ENTIDAD!$B$2:$C$613,2,0)) -> J&H CASA LINDA E.I.R.L. | N28: =(S28-P28)/1.18 -> 0 | O28: =N28*0.18 -> 0 | P28: 615 | R28: 0 | S28: 615 | AB28: S | AD28: 46035 | AE28: CRE | AF28: 6344095 | AH28: 4212 | AR28: 18 | AS28: POR LA COMPRA DE CERAMICA
A29: 46035 | C29: 01 | D29: 00F005 | F29: 530 | G29: 6 | H29: 20602109225 | I29: =IF(H29="","",VLOOKUP(H29,ENTIDAD!$B$2:$C$613,2,0)) -> SISTEMA ECOLÓGICO INTEGRAL DE TECNOLOGÍAS E INFORMÁTICA SOCIEDAD ANONIMA CERRADA - ECO SITI S.A.C. | N29: =(S29-P29)/1.18 -> 0 | O29: =N29*0.18 -> 0 | P29: 119.7 | R29: 0 | S29: 119.7 | AB29: S | AD29: 46035 | AE29: CON | AF29: 6364095 | AH29: 4212 | AR29: 18 | AS29: POR EL SERVICIO DE LLAMADAS
A30: 46036 | C30: 01 | D30: 00F001 | F30: 5117 | G30: 6 | H30: 10061702071 | I30: =IF(H30="","",VLOOKUP(H30,ENTIDAD!$B$2:$C$613,2,0)) -> CORAL FLORES IVAN MARTIN | N30: =(S30-P30)/1.18 -> 0 | O30: =N30*0.18 -> 0 | P30: 645 | R30: 0 | S30: 645 | AB30: S | AD30: 46036 | AE30: CRE | AF30: 6329095 | AG30: 1413 | AH30: 4212 | AR30: 18 | AS30: POR EL SERVICIO DE LEGALIZACION
A31: 46037 | C31: 01 | D31: 00FF08 | F31: 708 | G31: 6 | H31: 20611526572 | I31: =IF(H31="","",VLOOKUP(H31,ENTIDAD!$B$2:$C$613,2,0)) -> GRUPO SUKKIE E.I.R.L. | N31: =(S31-P31)/1.18 -> 0 | O31: =N31*0.18 -> 0 | P31: 61.2 | R31: 0 | S31: 61.2 | AB31: S | AD31: 46037 | AE31: CON | AF31: 656009502 | AH31: 4212 | AR31: 18 | AS31: POR LA COMPRA DE ARTICULOS DE LIMPIEZA
A32: 46037 | C32: 01 | D32: 00F005 | F32: 16314 | G32: 6 | H32: 20493508645 | I32: =IF(H32="","",VLOOKUP(H32,ENTIDAD!$B$2:$C$613,2,0)) -> HONDA SELVA DEL PERU S.A. | N32: =(S32-P32)/1.18 -> 0.00040677966 | O32: =N32*0.18 -> 7.3220338e-05 | P32: 61102.43 | S32: =W32*AC32 -> 61102.43 | W32: 3.367 | AB32: D | AC32: 18147.44 | AD32: 46068 | AE32: CRE | AF32: 6011021 | AH32: 4212 | AR32: 18 | AS32: EXISTENCIAS POR RECIBIR
A33: 46037 | C33: 01 | D33: 00FC01 | F33: 573296 | G33: 6 | H33: 20100047218 | I33: =IF(H33="","",VLOOKUP(H33,ENTIDAD!$B$2:$C$613,2,0)) -> BANCO DE CREDITO DEL PERU | N33: =(S33-P33)/1.18 -> 0 | O33: =N33*0.18 -> 0 | P33: 5503.5 | S33: 5503.5 | AB33: S | AD33: 46037 | AE33: CRE | AH33: 4212 | AR33: 18
A34: 46038 | C34: 01 | D34: 00F001 | F34: 15611 | G34: 6 | H34: 20444766906 | I34: =IF(H34="","",VLOOKUP(H34,ENTIDAD!$B$2:$C$613,2,0)) -> EMPRESA DE TRANSPORTES PROFAMSE SRL | N34: =(S34-P34)/1.18 -> 0 | O34: =N34*0.18 -> 0 | P34: 40 | R34: 0 | S34: 40 | AB34: S | AD34: 46038 | AE34: CRE | AF34: 6311295 | AG34: 1413 | AH34: 4212 | AR34: 18 | AS34: POR EL SERVICIO DE TRANSPORTE DE PASAJERO
A35: 46038 | C35: 01 | D35: 00E001 | F35: 1160 | G35: 6 | H35: 20485903811 | I35: =IF(H35="","",VLOOKUP(H35,ENTIDAD!$B$2:$C$613,2,0)) -> EMPRESA DE TRANSPORTES ECO TURISTICO SA | N35: =(S35-P35)/1.18 -> 0 | O35: =N35*0.18 -> 0 | P35: 40 | R35: 0 | S35: 40 | AB35: S | AD35: 46038 | AE35: CRE | AF35: 6311295 | AG35: 1413 | AH35: 4212 | AR35: 18 | AS35: POR EL SERVICIO DE TRANSPORTE DE PASAJERO
A36: 46038 | C36: 01 | D36: 00E001 | F36: 5965 | G36: 6 | H36: 20602783341 | I36: =IF(H36="","",VLOOKUP(H36,ENTIDAD!$B$2:$C$613,2,0)) -> CODISSER VRAEM E.I.R.L. | N36: =(S36-P36)/1.18 -> 0 | O36: =N36*0.18 -> 0 | P36: 16 | R36: 0 | S36: 16 | AB36: S | AD36: 46038 | AE36: CON | AF36: 6250095 | AH36: 4212 | AR36: 18 | AS36: POR LA COMPRA DE AGUA MESA
A37: 46038 | C37: 01 | D37: 00E001 | F37: 2281 | G37: 6 | H37: 20541326384 | I37: =IF(H37="","",VLOOKUP(H37,ENTIDAD!$B$2:$C$613,2,0)) -> AEROM INVERSIONES NEGOCIOS SERVICIOS E.I.R.L. | N37: =(S37-P37)/1.18 -> 0 | O37: =N37*0.18 -> 0 | P37: 46 | R37: 0 | S37: 46 | AB37: S | AD37: 46038 | AE37: CRE | AF37: 6344095 | AH37: 4212 | AR37: 18 | AS37: POR LA COMPRA DE PEGAMENTO EXTRAFUERTE
A38: 46038 | C38: 01 | D38: 00FN01 | F38: 41464917 | G38: 6 | H38: 20100047218 | I38: =IF(H38="","",VLOOKUP(H38,ENTIDAD!$B$2:$C$613,2,0)) -> BANCO DE CREDITO DEL PERU | N38: =(S38-P38)/1.18 -> 0 | O38: =N38*0.18 -> 0 | P38: 10 | S38: 10 | AB38: S | AD38: 46038 | AE38: CRE | AF38: 6391094 | AH38: 4212 | AR38: 18 | AS38: POR LA COMISION BANCARIA
A39: 46038 | C39: 01 | D39: 00FN01 | F39: 41464993 | G39: 6 | H39: 20100047218 | I39: =IF(H39="","",VLOOKUP(H39,ENTIDAD!$B$2:$C$613,2,0)) -> BANCO DE CREDITO DEL PERU | N39: =(S39-P39)/1.18 -> 0 | O39: =N39*0.18 -> 0 | P39: 10 | S39: 10 | AB39: S | AD39: 46038 | AE39: CRE | AF39: 6391094 | AH39: 4212 | AR39: 18 | AS39: POR LA COMISION BANCARIA
A40: 46039 | C40: 01 | D40: 00F001 | F40: 590 | G40: 6 | H40: 10733910921 | I40: =IF(H40="","",VLOOKUP(H40,ENTIDAD!$B$2:$C$613,2,0)) -> MADUEÑO HUAMAN LILI CLISSELY | N40: =(S40-P40)/1.18 -> 0 | O40: =N40*0.18 -> 0 | P40: 7 | R40: 0 | S40: 7 | AB40: S | AD40: 46039 | AE40: CON | AF40: 6560095 | AH40: 4212 | AR40: 18 | AS40: PINTURA SPRAY
...

Sheet FEBRERO
A1: FECHA DE EMISION DEL COMPROBANTE DE PAGO O DOCUMENTO | B1: FECHA DE VENCIMIENTO O FECHA DE PAGO | C1: COMPROBANTE DE PAGO O DOCUMENTO | F1: N° COMPROBANTE PAGO | G1: INFORMACION PROVEEDOR | J1: ADQUISICIONES GRAVADAS DESTINADAS A OPERACIONES GRAVADAS Y/O EXPORTACION | L1: ADQUISICIONES GRAVADAS DESTINADAS A OPERACIONES GRAVADAS Y/O DE EXPORTACION Y A OPERACIONES NO GRAVADAS | N1: ADQUISICIONES GRAVADAS DESTINADAS A OPERACIONES NO GRAVADAS | P1: VALOR DE LAS ADQUISICIONES NO GRAVADAS | Q1: ISC | R1: OTROS TRIBUTOS Y CARGOS | S1: IMPORTE TOTAL | T1: N° COMPROBANTE DE PAGO EMITIDO POR SUJETO NO DOMICILIADO | U1: CONSTANCIA DE DEPOSITO DE DETRACCION | W1: TIPO DE CAMBIO | X1: REFERENCIA DEL COMPROBANTE DE PAGO O DOCUMENTO ORIGINAL QUE SE MODIFICA | AB1: MONEDA | AC1: EQUIVALENTE EN DOLARES AMERICANOS | AD1: FECHA VENCIMIENTO | AE1: CONDICION CONTADO/CREDITO | AF1: CUENTA CONTABLE BASE IMPONIBLE | AG1: CUENTA CONTABLE OTROS TRIBUTOS Y CARGOS | AH1: CUENTA CONTABLE TOTAL | AI1: CODIGO CENTRO DE COSTOS | AJ1: CODIGO CENTRO DE COSTOS 2 | AK1: REGIMEN ESPECIAL | AL1: PORCENTAJE REGIMEN ESPECIAL | AM1: IMPORTE REGIMEN ESPECIAL | AN1: SERIE DOCUMENTO REGIMEN ESPECIAL | AO1: NUMERO DOCUMENTO REGIMEN ESPECIAL | AP1: FECHA DOCUMENTO REGIMEN ESPECIAL | AQ1: CODIGO PRESUPUESTO | AR1: PORCENTAJE I.G.V. | AS1: GLOSA | AT1: CONDICIÓN DE PERCEPCIÓN | AU1: IMPORTE RÉGIMEN ESPECIAL | AV1: CLASIFICACIÓN DE BIENES Y SERVICIOS ADQUIRIDOS
G2: DOCUMENTO IDENTIDAD | I2: APELLIDOS Y NOMBRES, DENOMINACION O RAZON SOCIAL
C3: TIPO | D3: SERIE/CODIGO ADUANA | E3: AÑO EMISION DUA O DSI | G3: TIPO | H3: NUMERO | J3: BASE IMPONIBLE | K3: IGV | L3: BASE IMPONIBLE | M3: IGV | N3: BASE IMPONIBLE | O3: IGV | U3: NUMERO | V3: FECHA EMISION | X3: FECHA | Y3: TIPO | Z3: SERIE | AA3: N° COMPROBANTE PAGO O DOCUMENTO
A4: 46051 | C4: 14 | D4: 00S898 | F4: 5654883 | G4: 6 | H4: 20129646099 | I4: =IF(H4="","",VLOOKUP(H4,ENTIDAD!$B$2:$C$613,2,0)) -> ELECTROCENTRO S.A. | N4: =(S4-P4)/1.18 -> 0 | O4: =N4*0.18 -> 0 | P4: 93.5 | S4: 93.5 | AB4: S | AD4: 46067 | AE4: CRE | AF4: 6361095 | AH4: 4212 | AR4: 18 | AS4: POR EL SERVICIO DE ENERGIA ELECTRICA
A5: 46051 | C5: 14 | D5: 00S898 | F5: 5654878 | G5: 6 | H5: 20129646099 | I5: =IF(H5="","",VLOOKUP(H5,ENTIDAD!$B$2:$C$613,2,0)) -> ELECTROCENTRO S.A. | N5: =(S5-P5)/1.18 -> 0 | O5: =N5*0.18 -> 0 | P5: 440 | S5: 440 | AB5: S | AD5: 46067 | AE5: CRE | AF5: 6361095 | AH5: 4212 | AR5: 18 | AS5: POR EL SERVICIO DE ENERGIA ELECTRICA
A6: 46051 | C6: 14 | D6: 00S898 | F6: 5655102 | G6: 6 | H6: 20129646099 | I6: =IF(H6="","",VLOOKUP(H6,ENTIDAD!$B$2:$C$613,2,0)) -> ELECTROCENTRO S.A. | N6: =(S6-P6)/1.18 -> 0 | O6: =N6*0.18 -> 0 | P6: 534.7 | S6: 534.7 | AB6: S | AD6: 46067 | AE6: CRE | AF6: 6361095 | AH6: 4212 | AR6: 18 | AS6: POR EL SERVICIO DE ENERGIA ELECTRICA
A7: 46053 | C7: 14 | D7: 000060 | F7: 1051587 | G7: 6 | H7: 20121876290 | I7: =IF(H7="","",VLOOKUP(H7,ENTIDAD!$B$2:$C$613,2,0)) -> ENT.PREST.SERV.SANEAM.SELVA CENTRAL S.A | N7: =(S7-P7)/1.18 -> 0 | O7: =N7*0.18 -> 0 | P7: 46.76 | S7: 46.76 | AB7: S | AD7: 46081 | AE7: CRE | AF7: 6363095 | AH7: 4212 | AR7: 18 | AS7: POR EL SERVICIO DE AGUA POTABLE
A8: 46053 | C8: 14 | D8: 000060 | F8: 1050833 | G8: 6 | H8: 20121876290 | I8: =IF(H8="","",VLOOKUP(H8,ENTIDAD!$B$2:$C$613,2,0)) -> ENT.PREST.SERV.SANEAM.SELVA CENTRAL S.A | N8: =(S8-P8)/1.18 -> 0 | O8: =N8*0.18 -> 0 | P8: 46.76 | S8: 46.76 | AB8: S | AD8: 46081 | AE8: CRE | AF8: 6363095 | AH8: 4212 | AR8: 18 | AS8: POR EL SERVICIO DE AGUA POTABLE
A9: 46053 | C9: 14 | D9: 000060 | F9: 1052362 | G9: 6 | H9: 20121876290 | I9: =IF(H9="","",VLOOKUP(H9,ENTIDAD!$B$2:$C$613,2,0)) -> ENT.PREST.SERV.SANEAM.SELVA CENTRAL S.A | N9: =(S9-P9)/1.18 -> 0 | O9: =N9*0.18 -> 0 | P9: 45.8 | S9: 45.8 | AB9: S | AD9: 46081 | AE9: CRE | AF9: 6363095 | AH9: 4212 | AR9: 18 | AS9: POR EL SERVICIO DE AGUA POTABLE
A10: 46054 | C10: 14 | D10: 00SB01 | F10: 601019205 | G10: 6 | H10: 20467534026 | I10: =IF(H10="","",VLOOKUP(H10,ENTIDAD!$B$2:$C$613,2,0)) -> AMERICA MOVIL PERU S.A.C. | N10: =(S10-P10)/1.18 -> 75.177966 | O10: =N10*0.18 -> 13.532034 | P10: -0.01 | S10: 88.7 | AB10: S | AD10: 46072 | AE10: CRE | AF10: 6365095 | AH10: 4212 | AR10: 18 | AS10: POR EL SERVICIO DE INTERNET
A11: 46055 | C11: 01 | D11: 00FB25 | F11: 25807856 | G11: 6 | H11: 20100130204 | I11: =IF(H11="","",VLOOKUP(H11,ENTIDAD!$B$2:$C$613,2,0)) -> BANCO BBVA PERU | N11: =(S11-P11)/1.18 -> 0 | O11: =N11*0.18 -> 0 | P11: 10 | S11: 10 | AB11: S | AD11: 46083 | AE11: CRE | AF11: 6391094 | AH11: 4212 | AR11: 18 | AS11: POR LA COMISION BANCARIA
A12: 46056 | C12: 01 | D12: 00E001 | F12: 1855 | G12: 6 | H12: 20568570520 | I12: =IF(H12="","",VLOOKUP(H12,ENTIDAD!$B$2:$C$613,2,0)) -> INVERSIONES IRWIN E.I.R.L. | N12: =(S12-P12)/1.18 -> 0 | O12: =N12*0.18 -> 0 | P12: 36 | S12: 36 | AB12: S | AE12: CON | AF12: 656009504 | AH12: 4212 | AR12: 18 | AS12: BOYA DE BRONCE
A13: 46056 | C13: 01 | D13: 00F001 | F13: 619 | G13: 6 | H13: 10733910921 | I13: =IF(H13="","",VLOOKUP(H13,ENTIDAD!$B$2:$C$613,2,0)) -> MADUEÑO HUAMAN LILI CLISSELY | N13: =(S13-P13)/1.18 -> 0 | O13: =N13*0.18 -> 0 | P13: 22 | S13: 22 | AB13: S | AE13: CON | AF13: 656009504 | AH13: 4212 | AR13: 18 | AS13: DADO HEXAGONAL
A14: 46056 | C14: 01 | D14: 00FC04 | F14: 4782894 | G14: 6 | H14: 20100130204 | I14: =IF(H14="","",VLOOKUP(H14,ENTIDAD!$B$2:$C$613,2,0)) -> BANCO BBVA PERU | N14: =(S14-P14)/1.18 -> 0 | O14: =N14*0.18 -> 0 | P14: 40 | S14: 40 | AB14: S | AD14: 46084 | AE14: CRE | AF14: 6391094 | AH14: 4212 | AR14: 18 | AS14: POR LA COMISION BANCARIA
A15: 46057 | C15: 01 | D15: 00E001 | F15: 1773 | G15: 6 | H15: 20486339510 | I15: =IF(H15="","",VLOOKUP(H15,ENTIDAD!$B$2:$C$613,2,0)) -> SERVICIOS CONTABLES Y AUDITORIA INTERNA S.A. | N15: =(S15-P15)/1.18 -> 1694.9153 | O15: =N15*0.18 -> 305.08475 | S15: 2000 | AB15: S | AD15: 46085 | AE15: CRE | AF15: 6323094 | AH15: 4212 | AR15: 18 | AS15: SERVICIO CONTABLE
A16: 46057 | C16: 01 | D16: 00FE01 | F16: 2692474 | G16: 6 | H16: 20100047218 | I16: =IF(H16="","",VLOOKUP(H16,ENTIDAD!$B$2:$C$613,2,0)) -> BANCO DE CREDITO DEL PERU | N16: =(S16-P16)/1.18 -> -0.0042372881 | O16: =N16*0.18 -> -0.00076271186 | P16: 117.78 | S16: =W16*AC16 -> 117.775 | W16: 3.365 | AB16: D | AC16: 35 | AD16: 46085 | AE16: CRE | AF16: 6391094 | AH16: 4212 | AR16: 18 | AS16: POR LA COMISION BANCARIA
A17: 46057 | C17: 01 | D17: 00FF01 | F17: 61 | G17: 6 | H17: 10421947665 | I17: =IF(H17="","",VLOOKUP(H17,ENTIDAD!$B$2:$C$613,2,0)) -> MAYTA,MADUEÑO,SAUL,JESUS | N17: =(S17-P17)/1.18 -> 0 | O17: =N17*0.18 -> 0 | P17: 60 | S17: 60 | AB17: S | AE17: CON | AF17: 656009502 | AH17: 4212 | AR17: 18 | AS17: POR LA COMPRA DE ARTICULOS DE LIMPIEZA
A18: 46057 | C18: 01 | D18: 00E001 | F18: 152 | G18: 6 | H18: 10447422951 | I18: =IF(H18="","",VLOOKUP(H18,ENTIDAD!$B$2:$C$613,2,0)) -> ZEGARRA AZAÑERO JORGE KEY | N18: =(S18-P18)/1.18 -> 0 | O18: =N18*0.18 -> 0 | P18: 450 | S18: 450 | AB18: S | AD18: 46085 | AE18: CRE | AF18: 6329094 | AH18: 4212 | AR18: 18 | AS18: SOPORTE TECNICO
A19: 46058 | C19: 01 | D19: 00F001 | F19: 8322 | G19: 6 | H19: 20610959432 | I19: =IF(H19="","",VLOOKUP(H19,ENTIDAD!$B$2:$C$613,2,0)) -> SERVICENTRO CRISNEYA EMPRESA INDIVIDUAL DE RESPONSABILIDAD LIMITADA | N19: =(S19-P19)/1.18 -> 0 | O19: =N19*0.18 -> 0 | P19: 10 | S19: 10 | AB19: S | AE19: CON | AF19: 656009501 | AH19: 4212 | AR19: 18 | AS19: POR LA COMPRA DE COMBUSTIBLE
A20: 46058 | C20: 01 | D20: 00FF01 | F20: 64 | G20: 6 | H20: 10421947665 | I20: =IF(H20="","",VLOOKUP(H20,ENTIDAD!$B$2:$C$613,2,0)) -> MAYTA,MADUEÑO,SAUL,JESUS | N20: =(S20-P20)/1.18 -> 0 | O20: =N20*0.18 -> 0 | P20: 9.5 | S20: 9.5 | AB20: S | AE20: CON | AF20: 656009502 | AH20: 4212 | AR20: 18 | AS20: POR LA COMPRA DE LIMPIAVIDRIOS
A21: 46058 | C21: 01 | D21: 00F006 | F21: 3448 | G21: 6 | H21: 20568909128 | I21: =IF(H21="","",VLOOKUP(H21,ENTIDAD!$B$2:$C$613,2,0)) -> MESSENGER WORLD E.I.R.L | N21: =(S21-P21)/1.18 -> 12.711864 | O21: =N21*0.18 -> 2.2881356 | P21: 0 | S21: 15 | AB21: S | AD21: 46086 | AE21: CRE | AF21: 6311195 | AH21: 4212 | AR21: 18 | AS21: POR EL SERVICIO DE TRANSPORTE
A22: 46058 | C22: 01 | D22: 00F001 | F22: 5421 | G22: 6 | H22: 10421947665 | I22: =IF(H22="","",VLOOKUP(H22,ENTIDAD!$B$2:$C$613,2,0)) -> MAYTA,MADUEÑO,SAUL,JESUS | N22: =(S22-P22)/1.18 -> 0 | O22: =N22*0.18 -> 0 | P22: 36 | S22: 36 | AB22: S | AE22: CON | AF22: 656009502 | AH22: 4212 | AR22: 18 | AS22: POR LA COMPRA DE ARTICULOS DE LIMPIEZA
A23: 46058 | C23: 01 | D23: 00E001 | F23: 5998 | G23: 6 | H23: 20602783341 | I23: =IF(H23="","",VLOOKUP(H23,ENTIDAD!$B$2:$C$613,2,0)) -> CODISSER VRAEM E.I.R.L. | N23: =(S23-P23)/1.18 -> 0 | O23: =N23*0.18 -> 0 | P23: 8 | S23: 8 | AB23: S | AE23: CON | AF23: 6250095 | AH23: 4212 | AR23: 18 | AS23: POR LA COMPRA DE AGUA MESA
A24: 46058 | C24: 01 | D24: 00F002 | F24: 133 | G24: 6 | H24: 20600454065 | I24: =IF(H24="","",VLOOKUP(H24,ENTIDAD!$B$2:$C$613,2,0)) -> REPUESTOS Y SERVICIOS ARAUCO E.I.R.L. | N24: =(S24-P24)/1.18 -> 0 | O24: =N24*0.18 -> 0 | P24: 2670 | S24: 2670 | AB24: S | AE24: CRE | AF24: 6343095 | AH24: 4212 | AR24: 18 | AS24: MANTENIMIENTO DE MOTOS VENDIDAS - GARANTIA
A25: 46060 | C25: 01 | D25: 00FI01 | F25: 18308599 | G25: 6 | H25: 20100047218 | I25: =IF(H25="","",VLOOKUP(H25,ENTIDAD!$B$2:$C$613,2,0)) -> BANCO DE CREDITO DEL PERU | N25: =(S25-P25)/1.18 -> 0 | O25: =N25*0.18 -> 0 | P25: 987.48 | S25: 987.48 | AB25: S | AD25: 46088 | AE25: CRE | AF25: 6391094 | AH25: 4212 | AR25: 18 | AS25: POR LA COMISION BANCARIA
A26: 46060 | C26: 01 | D26: 00F001 | F26: 5167 | G26: 6 | H26: 10061702071 | I26: =IF(H26="","",VLOOKUP(H26,ENTIDAD!$B$2:$C$613,2,0)) -> CORAL FLORES IVAN MARTIN | N26: =(S26-P26)/1.18 -> 0 | O26: =N26*0.18 -> 0 | P26: 455 | S26: 455 | AB26: S | AD26: 46088 | AE26: CRE | AF26: 6599095 | AG26: 1413 | AH26: 4212 | AR26: 18 | AS26: POR EL SERVICIO DE LEGALIZACION
A27: 46060 | C27: 01 | D27: 00E001 | F27: 659 | G27: 6 | H27: 10433685721 | I27: =IF(H27="","",VLOOKUP(H27,ENTIDAD!$B$2:$C$613,2,0)) -> MANDUJANO,SOLANO,JOSE,ELIAS | N27: =(S27-P27)/1.18 -> 0 | O27: =N27*0.18 -> 0 | P27: 14 | S27: 14 | AB27: S | AE27: CON | AF27: 656009503 | AH27: 4212 | AR27: 18 | AS27: POR LA COMPRA DE VINIFAN
A28: 46060 | C28: 01 | D28: 00FV14 | F28: 1292611 | G28: 6 | H28: 20100047218 | I28: =IF(H28="","",VLOOKUP(H28,ENTIDAD!$B$2:$C$613,2,0)) -> BANCO DE CREDITO DEL PERU | N28: =(S28-P28)/1.18 -> 0 | O28: =N28*0.18 -> 0 | P28: 132.5 | S28: 132.5 | AB28: S | AE28: CRE | AF28: 6391094 | AH28: 4212 | AR28: 18 | AS28: OPERACIÓN POR EXCESO
A29: 46063 | C29: 01 | D29: 00F001 | F29: 117458 | G29: 6 | H29: 20568499043 | I29: =IF(H29="","",VLOOKUP(H29,ENTIDAD!$B$2:$C$613,2,0)) -> SURTIDORES SAN MIGUEL E.I.R.L. | N29: =(S29-P29)/1.18 -> 0 | O29: =N29*0.18 -> 0 | P29: 100 | S29: 100 | AB29: S | AE29: CON | AF29: 656009401 | AH29: 4212 | AR29: 18 | AS29: POR LA COMPRA DE COMBUSTIBLE
A30: 46063 | C30: 01 | D30: 00E001 | F30: 12000 | G30: 6 | H30: 20568968051 | I30: =IF(H30="","",VLOOKUP(H30,ENTIDAD!$B$2:$C$613,2,0)) -> AUTOMOVIL SATIPO TOURS S.A.C. | N30: =(S30-P30)/1.18 -> 0 | O30: =N30*0.18 -> 0 | P30: 40 | S30: 40 | AB30: S | AD30: 46091 | AE30: CRE | AF30: 6599095 | AG30: 1413 | AH30: 4212 | AR30: 18 | AS30: POR EL SERVICIO DE TRANSPORTE DE PASAJERO
A31: 46063 | C31: 01 | D31: 00F001 | F31: 15741 | G31: 6 | H31: 20444766906 | I31: =IF(H31="","",VLOOKUP(H31,ENTIDAD!$B$2:$C$613,2,0)) -> EMPRESA DE TRANSPORTES PROFAMSE SRL | N31: =(S31-P31)/1.18 -> 0 | O31: =N31*0.18 -> 0 | P31: 40 | S31: 40 | AB31: S | AD31: 46091 | AE31: CRE | AF31: 6599095 | AG31: 1413 | AH31: 4212 | AR31: 18 | AS31: POR EL SERVICIO DE TRANSPORTE DE PASAJERO
A32: 46065 | C32: 01 | D32: 00F002 | F32: 2133 | G32: 6 | H32: 20603851171 | I32: =IF(H32="","",VLOOKUP(H32,ENTIDAD!$B$2:$C$613,2,0)) -> J&J RENATO E.I.R.L. | N32: =(S32-P32)/1.18 -> 0 | O32: =N32*0.18 -> 0 | P32: 3 | S32: 3 | AB32: S | AE32: CON | AF32: 656009504 | AH32: 4212 | AR32: 18 | AS32: POR LA COMPRA DE JEBE
A33: 46065 | C33: 01 | D33: 00F002 | F33: 173 | G33: 6 | H33: 10209907327 | I33: =IF(H33="","",VLOOKUP(H33,ENTIDAD!$B$2:$C$613,2,0)) -> TORPOCO,MAYTA,HECTOR,ALFONSO | N33: =(S33-P33)/1.18 -> 0 | O33: =N33*0.18 -> 0 | P33: 5 | S33: 5 | AB33: S | AE33: CON | AF33: 656009501 | AH33: 4212 | AR33: 18 | AS33: POR LA COMPRA DE COMBUSTIBLE
A34: 46065 | C34: 01 | D34: 00F006 | F34: 425 | G34: 6 | H34: 20568369000 | I34: =IF(H34="","",VLOOKUP(H34,ENTIDAD!$B$2:$C$613,2,0)) -> INFORMATICA Y GRAFICA EMPRESA INDIVIDUAL DE RESPONSABILIDAD LIMITADA - INFOGRAFIC E.I.R.L. | N34: =(S34-P34)/1.18 -> 0 | O34: =N34*0.18 -> 0 | P34: 40 | S34: 40 | AB34: S | AE34: CON | AF34: 656009506 | AH34: 4212 | AR34: 18 | AS34: POR LA COMPRA DE TINTA DE IMPRESORA
A35: 46065 | C35: 01 | D35: 00F028 | F35: 14845 | G35: 6 | H35: 20493508645 | I35: =IF(H35="","",VLOOKUP(H35,ENTIDAD!$B$2:$C$613,2,0)) -> HONDA SELVA DEL PERU S.A. | N35: =(S35-P35)/1.18 -> 0.0038389831 | O35: =N35*0.18 -> 0.00069101695 | P35: 13029.3 | S35: =W35*AC35 -> 13029.305 | W35: 3.363 | AB35: D | AC35: 3874.31 | AD35: 46093 | AE35: CRE | AF35: 6011021 | AH35: 4212 | AR35: 18 | AS35: EXISTENCIAS POR RECIBIR
A36: 46066 | C36: 01 | D36: 00F003 | F36: 3637109 | G36: 6 | H36: 20101973922 | I36: =IF(H36="","",VLOOKUP(H36,ENTIDAD!$B$2:$C$613,2,0)) -> ASOCIACION AUTOMOTRIZ DEL PERU | N36: 0 | O36: =N36*0.18 -> 0 | P36: 0 | R36: 66.8 | S36: 66.8 | AB36: S | AD36: 46094 | AE36: CRE | AF36: 6599095 | AG36: 1413 | AH36: 4212 | AR36: 18 | AS36: POR DERECHO DE EMISION DE PLACA DE RODAJE
A37: 46066 | C37: 01 | D37: 00F003 | F37: 3637110 | G37: 6 | H37: 20101973922 | I37: =IF(H37="","",VLOOKUP(H37,ENTIDAD!$B$2:$C$613,2,0)) -> ASOCIACION AUTOMOTRIZ DEL PERU | N37: 0 | O37: =N37*0.18 -> 0 | P37: 0 | R37: 66.8 | S37: 66.8 | AB37: S | AD37: 46094 | AE37: CRE | AF37: 6599095 | AG37: 1413 | AH37: 4212 | AR37: 18 | AS37: POR DERECHO DE EMISION DE PLACA DE RODAJE
A38: 46066 | C38: 01 | D38: 00F003 | F38: 3637111 | G38: 6 | H38: 20101973922 | I38: =IF(H38="","",VLOOKUP(H38,ENTIDAD!$B$2:$C$613,2,0)) -> ASOCIACION AUTOMOTRIZ DEL PERU | N38: 0 | O38: =N38*0.18 -> 0 | P38: 0 | R38: 66.8 | S38: 66.8 | AB38: S | AD38: 46094 | AE38: CRE | AF38: 6599095 | AG38: 1413 | AH38: 4212 | AR38: 18 | AS38: POR DERECHO DE EMISION DE PLACA DE RODAJE
A39: 46066 | C39: 01 | D39: 00F003 | F39: 3637112 | G39: 6 | H39: 20101973922 | I39: =IF(H39="","",VLOOKUP(H39,ENTIDAD!$B$2:$C$613,2,0)) -> ASOCIACION AUTOMOTRIZ DEL PERU | N39: 0 | O39: =N39*0.18 -> 0 | P39: 0 | R39: 66.8 | S39: 66.8 | AB39: S | AD39: 46094 | AE39: CRE | AF39: 6599095 | AG39: 1413 | AH39: 4212 | AR39: 18 | AS39: POR DERECHO DE EMISION DE PLACA DE RODAJE
A40: 46066 | C40: 01 | D40: 00F003 | F40: 3637113 | G40: 6 | H40: 20101973922 | I40: =IF(H40="","",VLOOKUP(H40,ENTIDAD!$B$2:$C$613,2,0)) -> ASOCIACION AUTOMOTRIZ DEL PERU | N40: 0 | O40: =N40*0.18 -> 0 | P40: 0 | R40: 66.8 | S40: 66.8 | AB40: S | AD40: 46094 | AE40: CRE | AF40: 6599095 | AG40: 1413 | AH40: 4212 | AR40: 18 | AS40: POR DERECHO DE EMISION DE PLACA DE RODAJE
...

Sheet MARZO
A1: FECHA DE EMISION DEL COMPROBANTE DE PAGO O DOCUMENTO | B1: FECHA DE VENCIMIENTO O FECHA DE PAGO | C1: COMPROBANTE DE PAGO O DOCUMENTO | F1: N° COMPROBANTE PAGO | G1: INFORMACION PROVEEDOR | J1: ADQUISICIONES GRAVADAS DESTINADAS A OPERACIONES GRAVADAS Y/O EXPORTACION | L1: ADQUISICIONES GRAVADAS DESTINADAS A OPERACIONES GRAVADAS Y/O DE EXPORTACION Y A OPERACIONES NO GRAVADAS | N1: ADQUISICIONES GRAVADAS DESTINADAS A OPERACIONES NO GRAVADAS | P1: VALOR DE LAS ADQUISICIONES NO GRAVADAS | Q1: ISC | R1: OTROS TRIBUTOS Y CARGOS | S1: IMPORTE TOTAL | T1: N° COMPROBANTE DE PAGO EMITIDO POR SUJETO NO DOMICILIADO | U1: CONSTANCIA DE DEPOSITO DE DETRACCION | W1: TIPO DE CAMBIO | X1: REFERENCIA DEL COMPROBANTE DE PAGO O DOCUMENTO ORIGINAL QUE SE MODIFICA | AB1: MONEDA | AC1: EQUIVALENTE EN DOLARES AMERICANOS | AD1: FECHA VENCIMIENTO | AE1: CONDICION CONTADO/CREDITO | AF1: CUENTA CONTABLE BASE IMPONIBLE | AG1: CUENTA CONTABLE OTROS TRIBUTOS Y CARGOS | AH1: CUENTA CONTABLE TOTAL | AI1: CODIGO CENTRO DE COSTOS | AJ1: CODIGO CENTRO DE COSTOS 2 | AK1: REGIMEN ESPECIAL | AL1: PORCENTAJE REGIMEN ESPECIAL | AM1: IMPORTE REGIMEN ESPECIAL | AN1: SERIE DOCUMENTO REGIMEN ESPECIAL | AO1: NUMERO DOCUMENTO REGIMEN ESPECIAL | AP1: FECHA DOCUMENTO REGIMEN ESPECIAL | AQ1: CODIGO PRESUPUESTO | AR1: PORCENTAJE I.G.V. | AS1: GLOSA | AT1: CONDICIÓN DE PERCEPCIÓN | AU1: IMPORTE RÉGIMEN ESPECIAL | AV1: CLASIFICACIÓN DE BIENES Y SERVICIOS ADQUIRIDOS
G2: DOCUMENTO IDENTIDAD | I2: APELLIDOS Y NOMBRES, DENOMINACION O RAZON SOCIAL
C3: TIPO | D3: SERIE/CODIGO ADUANA | E3: AÑO EMISION DUA O DSI | G3: TIPO | H3: NUMERO | J3: BASE IMPONIBLE | K3: IGV | L3: BASE IMPONIBLE | M3: IGV | N3: BASE IMPONIBLE | O3: IGV | U3: NUMERO | V3: FECHA EMISION | X3: FECHA | Y3: TIPO | Z3: SERIE | AA3: N° COMPROBANTE PAGO O DOCUMENTO
A4: 46079 | C4: 14 | D4: 00S898 | F4: 5692682 | G4: 6 | H4: 20129646099 | I4: =IF(H4="","",VLOOKUP(H4,ENTIDAD!$B$2:$C$613,2,0)) -> ELECTROCENTRO S.A. | N4: 0 | O4: =N4*0.18 -> 0 | P4: 375.4 | S4: 375.4 | AB4: S | AD4: 46095 | AE4: CRE | AF4: 6361095 | AH4: 4212 | AR4: 18 | AS4: POR EL SERVICIO DE ENERGIA ELECTRICA
A5: 46079 | C5: 14 | D5: 00S898 | F5: 5692906 | G5: 6 | H5: 20129646099 | I5: =IF(H5="","",VLOOKUP(H5,ENTIDAD!$B$2:$C$613,2,0)) -> ELECTROCENTRO S.A. | N5: =(S5-P5)/1.18 -> 0 | O5: =N5*0.18 -> 0 | P5: 484.8 | S5: 484.8 | AB5: S | AD5: 46095 | AE5: CRE | AF5: 6361095 | AH5: 4212 | AR5: 18 | AS5: POR EL SERVICIO DE ENERGIA ELECTRICA
A6: 46079 | C6: 14 | D6: 00S898 | F6: 5692687 | G6: 6 | H6: 20129646099 | I6: =IF(H6="","",VLOOKUP(H6,ENTIDAD!$B$2:$C$613,2,0)) -> ELECTROCENTRO S.A. | N6: 0 | O6: =N6*0.18 -> 0 | P6: 83.2 | S6: 83.2 | AB6: S | AD6: 46095 | AE6: CRE | AF6: 6361095 | AH6: 4212 | AR6: 18 | AS6: POR EL SERVICIO DE ENERGIA ELECTRICA
A7: 46081 | C7: 14 | D7: 00S060 | F7: 1056363 | G7: 6 | H7: 20121876290 | I7: =IF(H7="","",VLOOKUP(H7,ENTIDAD!$B$2:$C$613,2,0)) -> ENT.PREST.SERV.SANEAM.SELVA CENTRAL S.A | N7: 0 | O7: =N7*0.18 -> 0 | P7: 46.8 | S7: 46.8 | AB7: S | AD7: 46112 | AE7: CRE | AF7: 6363095 | AH7: 4212 | AR7: 18 | AS7: POR EL SERVICIO DE AGUA POTABLE
A8: 46081 | C8: 14 | D8: 00S060 | F8: 1057146 | G8: 6 | H8: 20121876290 | I8: =IF(H8="","",VLOOKUP(H8,ENTIDAD!$B$2:$C$613,2,0)) -> ENT.PREST.SERV.SANEAM.SELVA CENTRAL S.A | N8: 0 | O8: =N8*0.18 -> 0 | P8: 46.8 | S8: 46.8 | AB8: S | AD8: 46112 | AE8: CRE | AF8: 6363095 | AH8: 4212 | AR8: 18 | AS8: POR EL SERVICIO DE AGUA POTABLE
A9: 46081 | C9: 14 | D9: 00S060 | F9: 1057941 | G9: 6 | H9: 20121876290 | I9: =IF(H9="","",VLOOKUP(H9,ENTIDAD!$B$2:$C$613,2,0)) -> ENT.PREST.SERV.SANEAM.SELVA CENTRAL S.A | N9: =(S9-P9)/1.18 -> 0 | O9: =N9*0.18 -> 0 | P9: 39.4 | S9: 39.4 | AB9: S | AD9: 46112 | AE9: CRE | AF9: 6363095 | AH9: 4212 | AR9: 18 | AS9: POR EL SERVICIO DE AGUA POTABLE
A10: 46082 | C10: 14 | D10: 00SB01 | F10: 608275570 | G10: 6 | H10: 20467534026 | I10: =IF(H10="","",VLOOKUP(H10,ENTIDAD!$B$2:$C$613,2,0)) -> AMERICA MOVIL PERU S.A.C. | N10: =(S10-P10)/1.18 -> 75.423729 | O10: =N10*0.18 -> 13.576271 | P10: 0 | S10: 89 | AB10: S | AD10: 46100 | AE10: CRE | AF10: 6365095 | AH10: 4212 | AR10: 18 | AS10: POR EL SERVICIO DE INTERNET
A11: 46083 | C11: 01 | D11: 00E001 | F11: 1805 | G11: 6 | H11: 20486339510 | I11: =IF(H11="","",VLOOKUP(H11,ENTIDAD!$B$2:$C$613,2,0)) -> SERVICIOS CONTABLES Y AUDITORIA INTERNA S.A. | N11: =(S11-P11)/1.18 -> 1694.9153 | O11: =N11*0.18 -> 305.08475 | P11: 0 | S11: 2000 | AB11: S | AD11: 46114 | AE11: CRE | AF11: 6323094 | AH11: 4212 | AR11: 18 | AS11: SERVICIO CONTABLE
A12: 46083 | C12: 01 | D12: 00E001 | F12: 174 | G12: 6 | H12: 10447422951 | I12: =IF(H12="","",VLOOKUP(H12,ENTIDAD!$B$2:$C$613,2,0)) -> ZEGARRA AZAÑERO JORGE KEY | N12: =(S12-P12)/1.18 -> 0 | O12: =N12*0.18 -> 0 | P12: 450 | S12: 450 | AB12: S | AD12: 46114 | AE12: CRE | AF12: 6329094 | AH12: 4212 | AR12: 18 | AS12: SOPORTE TECNICO
A13: 46083 | C13: 01 | D13: 00FB26 | F13: 26256669 | G13: 6 | H13: 20100130204 | I13: =IF(H13="","",VLOOKUP(H13,ENTIDAD!$B$2:$C$613,2,0)) -> BANCO BBVA PERU | N13: =(S13-P13)/1.18 -> 0 | O13: =N13*0.18 -> 0 | P13: 10 | S13: 10 | AB13: S | AD13: 46114 | AE13: CRE | AF13: 6391094 | AH13: 4212 | AR13: 18 | AS13: POR LA COMISION BANCARIA
A14: 46084 | C14: 01 | D14: 00F011 | F14: 880 | G14: 6 | H14: 20601012261 | I14: =IF(H14="","",VLOOKUP(H14,ENTIDAD!$B$2:$C$613,2,0)) -> IMPORTADORA DE REPUESTOS LA ROCA E.I.R.L. | N14: =(S14-P14)/1.18 -> 0 | O14: =N14*0.18 -> 0 | P14: 50 | S14: 50 | AB14: S | AE14: CON | AF14: 6360095 | AH14: 4212 | AR14: 18 | AS14: BATERIA
A15: 46084 | C15: 01 | D15: 00FC04 | F15: 4872628 | G15: 6 | H15: 20100130204 | I15: =IF(H15="","",VLOOKUP(H15,ENTIDAD!$B$2:$C$613,2,0)) -> BANCO BBVA PERU | N15: =(S15-P15)/1.18 -> 0 | O15: =N15*0.18 -> 0 | P15: 40 | S15: 40 | AB15: S | AD15: 46115 | AE15: CRE | AF15: 6391094 | AH15: 4212 | AR15: 18 | AS15: POR LA COMISION BANCARIA
A16: 46084 | C16: 01 | D16: 00F001 | F16: 5209 | G16: 6 | H16: 10061702071 | I16: =IF(H16="","",VLOOKUP(H16,ENTIDAD!$B$2:$C$613,2,0)) -> CORAL FLORES IVAN MARTIN | N16: =(S16-P16)/1.18 -> 0 | O16: =N16*0.18 -> 0 | P16: 190 | S16: 190 | AB16: S | AD16: 46115 | AE16: CRE | AF16: 6599095 | AG16: 1413 | AH16: 4212 | AR16: 18 | AS16: POR EL SERVICIO DE LEGALIZACION
A17: 46084 | C17: 01 | D17: 00F001 | F17: 5208 | G17: 6 | H17: 10061702071 | I17: =IF(H17="","",VLOOKUP(H17,ENTIDAD!$B$2:$C$613,2,0)) -> CORAL FLORES IVAN MARTIN | N17: 0 | O17: =N17*0.18 -> 0 | P17: 150 | S17: 150 | AB17: S | AD17: 46115 | AE17: CRE | AF17: 6599095 | AG17: 1413 | AH17: 4212 | AR17: 18 | AS17: POR EL SERVICIO DE LEGALIZACION
A18: 46085 | C18: 01 | D18: 00F003 | F18: 3712044 | G18: 6 | H18: 20101973922 | I18: =IF(H18="","",VLOOKUP(H18,ENTIDAD!$B$2:$C$613,2,0)) -> ASOCIACION AUTOMOTRIZ DEL PERU | N18: 0 | O18: =N18*0.18 -> 0 | P18: 0 | R18: 66.8 | S18: 66.8 | AB18: S | AD18: 46116 | AE18: CRE | AF18: 6599095 | AG18: 1413 | AH18: 4212 | AR18: 18 | AS18: POR DERECHO DE EMISION DE PLACA DE RODAJE
A19: 46085 | C19: 01 | D19: 00F003 | F19: 3712045 | G19: 6 | H19: 20101973922 | I19: =IF(H19="","",VLOOKUP(H19,ENTIDAD!$B$2:$C$613,2,0)) -> ASOCIACION AUTOMOTRIZ DEL PERU | N19: 0 | O19: =N19*0.18 -> 0 | P19: 0 | R19: 66.8 | S19: 66.8 | AB19: S | AD19: 46116 | AE19: CRE | AF19: 6599095 | AG19: 1413 | AH19: 4212 | AR19: 18 | AS19: POR DERECHO DE EMISION DE PLACA DE RODAJE
A20: 46085 | C20: 01 | D20: 00F003 | F20: 3712046 | G20: 6 | H20: 20101973922 | I20: =IF(H20="","",VLOOKUP(H20,ENTIDAD!$B$2:$C$613,2,0)) -> ASOCIACION AUTOMOTRIZ DEL PERU | N20: 0 | O20: =N20*0.18 -> 0 | P20: 0 | R20: 66.8 | S20: 66.8 | AB20: S | AD20: 46116 | AE20: CRE | AF20: 6599095 | AG20: 1413 | AH20: 4212 | AR20: 18 | AS20: POR DERECHO DE EMISION DE PLACA DE RODAJE
A21: 46085 | C21: 01 | D21: 00F003 | F21: 3712047 | G21: 6 | H21: 20101973922 | I21: =IF(H21="","",VLOOKUP(H21,ENTIDAD!$B$2:$C$613,2,0)) -> ASOCIACION AUTOMOTRIZ DEL PERU | N21: 0 | O21: =N21*0.18 -> 0 | P21: 0 | R21: 66.8 | S21: 66.8 | AB21: S | AD21: 46116 | AE21: CRE | AF21: 6599095 | AG21: 1413 | AH21: 4212 | AR21: 18 | AS21: POR DERECHO DE EMISION DE PLACA DE RODAJE
A22: 46085 | C22: 01 | D22: 00F003 | F22: 3712048 | G22: 6 | H22: 20101973922 | I22: =IF(H22="","",VLOOKUP(H22,ENTIDAD!$B$2:$C$613,2,0)) -> ASOCIACION AUTOMOTRIZ DEL PERU | N22: 0 | O22: =N22*0.18 -> 0 | P22: 0 | R22: 66.8 | S22: 66.8 | AB22: S | AD22: 46116 | AE22: CRE | AF22: 6599095 | AG22: 1413 | AH22: 4212 | AR22: 18 | AS22: POR DERECHO DE EMISION DE PLACA DE RODAJE
A23: 46085 | C23: 01 | D23: 00F003 | F23: 3712049 | G23: 6 | H23: 20101973922 | I23: =IF(H23="","",VLOOKUP(H23,ENTIDAD!$B$2:$C$613,2,0)) -> ASOCIACION AUTOMOTRIZ DEL PERU | N23: 0 | O23: =N23*0.18 -> 0 | P23: 0 | R23: 66.8 | S23: 66.8 | AB23: S | AD23: 46116 | AE23: CRE | AF23: 6599095 | AG23: 1413 | AH23: 4212 | AR23: 18 | AS23: POR DERECHO DE EMISION DE PLACA DE RODAJE
A24: 46085 | C24: 01 | D24: 00F003 | F24: 3712050 | G24: 6 | H24: 20101973922 | I24: =IF(H24="","",VLOOKUP(H24,ENTIDAD!$B$2:$C$613,2,0)) -> ASOCIACION AUTOMOTRIZ DEL PERU | N24: 0 | O24: =N24*0.18 -> 0 | P24: 0 | R24: 66.8 | S24: 66.8 | AB24: S | AD24: 46116 | AE24: CRE | AF24: 6599095 | AG24: 1413 | AH24: 4212 | AR24: 18 | AS24: POR DERECHO DE EMISION DE PLACA DE RODAJE
A25: 46085 | C25: 01 | D25: 00F003 | F25: 3712051 | G25: 6 | H25: 20101973922 | I25: =IF(H25="","",VLOOKUP(H25,ENTIDAD!$B$2:$C$613,2,0)) -> ASOCIACION AUTOMOTRIZ DEL PERU | N25: 0 | O25: =N25*0.18 -> 0 | P25: 0 | R25: 66.8 | S25: 66.8 | AB25: S | AD25: 46116 | AE25: CRE | AF25: 6599095 | AG25: 1413 | AH25: 4212 | AR25: 18 | AS25: POR DERECHO DE EMISION DE PLACA DE RODAJE
A26: 46085 | C26: 04893713 | D26: 00F003 | F26: 3712052 | G26: 6 | H26: 20101973922 | I26: =IF(H26="","",VLOOKUP(H26,ENTIDAD!$B$2:$C$613,2,0)) -> ASOCIACION AUTOMOTRIZ DEL PERU | N26: 0 | O26: =N26*0.18 -> 0 | P26: 0 | R26: 66.8 | S26: 66.8 | AB26: S | AD26: 46116 | AE26: CRE | AF26: 6599095 | AG26: 1413 | AH26: 4212 | AR26: 18 | AS26: POR DERECHO DE EMISION DE PLACA DE RODAJE
A27: 46085 | C27: 01 | D27: 00F003 | F27: 3712053 | G27: 6 | H27: 20101973922 | I27: =IF(H27="","",VLOOKUP(H27,ENTIDAD!$B$2:$C$613,2,0)) -> ASOCIACION AUTOMOTRIZ DEL PERU | N27: 0 | O27: =N27*0.18 -> 0 | P27: 0 | R27: 66.8 | S27: 66.8 | AB27: S | AD27: 46116 | AE27: CRE | AF27: 6599095 | AG27: 1413 | AH27: 4212 | AR27: 18 | AS27: POR DERECHO DE EMISION DE PLACA DE RODAJE
A28: 46085 | C28: 01 | D28: 00F003 | F28: 3712054 | G28: 6 | H28: 20101973922 | I28: =IF(H28="","",VLOOKUP(H28,ENTIDAD!$B$2:$C$613,2,0)) -> ASOCIACION AUTOMOTRIZ DEL PERU | N28: 0 | O28: =N28*0.18 -> 0 | P28: 0 | R28: 66.8 | S28: 66.8 | AB28: S | AD28: 46116 | AE28: CRE | AF28: 6599095 | AG28: 1413 | AH28: 4212 | AR28: 18 | AS28: POR DERECHO DE EMISION DE PLACA DE RODAJE
A29: 46085 | C29: 01 | D29: 00F003 | F29: 3712055 | G29: 6 | H29: 20101973922 | I29: =IF(H29="","",VLOOKUP(H29,ENTIDAD!$B$2:$C$613,2,0)) -> ASOCIACION AUTOMOTRIZ DEL PERU | N29: 0 | O29: =N29*0.18 -> 0 | P29: 0 | R29: 66.8 | S29: 66.8 | AB29: S | AD29: 46116 | AE29: CRE | AF29: 6599095 | AG29: 1413 | AH29: 4212 | AR29: 18 | AS29: POR DERECHO DE EMISION DE PLACA DE RODAJE
... A37: 46085 | C37: 01 | D37: 00F003 | F37: 3712063 | G37: 6 | H37: 20101973922 | I37: =IF(H37="","",VLOOKUP(H37,ENTIDAD!$B$2:$C$613,2,0)) -> ASOCIACION AUTOMOTRIZ DEL PERU | N37: 0 | O37: =N37*0.18 -> 0 | P37: 0 | R37: 66.8 | S37: 66.8 | AB37: S | AD37: 46116 | AE37: CRE | AF37: 6599095 | AG37: 1413 | AH37: 4212 | AR37: 18 | AS37: POR DERECHO DE EMISION DE PLACA DE RODAJE
A38: 46086 | C38: 01 | D38: 00FV19 | F38: 1325589 | G38: 6 | H38: 20100047218 | I38: =IF(H38="","",VLOOKUP(H38,ENTIDAD!$B$2:$C$613,2,0)) -> BANCO DE CREDITO DEL PERU | N38: =(S38-P38)/1.18 -> 0 | O38: =N38*0.18 -> 0 | P38: 143.5 | S38: 143.5 | AB38: S | AE38: CON | AH38: 4212 | AR38: 18
A39: 46086 | C39: 01 | D39: 00F001 | F39: 274 | G39: 6 | H39: 20613928830 | I39: =IF(H39="","",VLOOKUP(H39,ENTIDAD!$B$2:$C$613,2,0)) -> EE.SS. TORRES EMPRESA INDIVIDUAL DE RESPONSABILIDAD LIMITADA | N39: =(S39-P39)/1.18 -> 0 | O39: =N39*0.18 -> 0 | P39: 10 | S39: 10 | AB39: S | AE39: CON | AF39: 656009501 | AH39: 4212 | AR39: 18 | AS39: POR LA COMPRA DE COMBUSTIBLE
A40: 46087 | C40: 01 | D40: 00FE01 | F40: 2766087 | G40: 6 | H40: 20100047218 | I40: =IF(H40="","",VLOOKUP(H40,ENTIDAD!$B$2:$C$613,2,0)) -> BANCO DE CREDITO DEL PERU | N40: =(S40-P40)/1.18 -> 0 | O40: =N40*0.18 -> 0 | P40: 120.12 | S40: =W40*AC40 -> 120.12 | W40: 3.432 | AB40: D | AC40: 35 | AD40: 46118 | AE40: CRE | AF40: 6391094 | AH40: 4212 | AR40: 18 | AS40: POR LA COMISION BANCARIA
A41: 46088 | C41: 01 | D41: 00FI01 | F41: 18900536 | G41: 6 | H41: 20100047218 | I41: =IF(H41="","",VLOOKUP(H41,ENTIDAD!$B$2:$C$613,2,0)) -> BANCO DE CREDITO DEL PERU | N41: =(S41-P41)/1.18 -> 0 | O41: =N41*0.18 -> 0 | P41: 566.5 | S41: 566.5 | AB41: S | AD41: 46119 | AE41: CRE | AF41: 6391094 | AH41: 4212 | AR41: 18 | AS41: POR LA COMISION BANCARIA
A42: 46088 | C42: 01 | D42: 00F003 | F42: 3719364 | G42: 6 | H42: 20101973922 | I42: =IF(H42="","",VLOOKUP(H42,ENTIDAD!$B$2:$C$613,2,0)) -> ASOCIACION AUTOMOTRIZ DEL PERU | N42: 0 | O42: =N42*0.18 -> 0 | P42: 0 | R42: 66.8 | S42: 66.8 | AB42: S | AD42: 46119 | AE42: CRE | AF42: 6599095 | AG42: 1413 | AH42: 4212 | AR42: 18 | AS42: POR DERECHO DE EMISION DE PLACA DE RODAJE
A43: 46088 | C43: 01 | D43: 00F003 | F43: 3719365 | G43: 6 | H43: 20101973922 | I43: =IF(H43="","",VLOOKUP(H43,ENTIDAD!$B$2:$C$613,2,0)) -> ASOCIACION AUTOMOTRIZ DEL PERU | N43: 0 | O43: =N43*0.18 -> 0 | P43: 0 | R43: 66.8 | S43: 66.8 | AB43: S | AD43: 46119 | AE43: CRE | AF43: 6599095 | AG43: 1413 | AH43: 4212 | AR43: 18 | AS43: POR DERECHO DE EMISION DE PLACA DE RODAJE
A44: 46088 | C44: 01 | D44: 00F003 | F44: 3719366 | G44: 6 | H44: 20101973922 | I44: =IF(H44="","",VLOOKUP(H44,ENTIDAD!$B$2:$C$613,2,0)) -> ASOCIACION AUTOMOTRIZ DEL PERU | N44: 0 | O44: =N44*0.18 -> 0 | P44: 0 | R44: 66.8 | S44: 66.8 | AB44: S | AD44: 46119 | AE44: CRE | AF44: 6599095 | AG44: 1413 | AH44: 4212 | AR44: 18 | AS44: POR DERECHO DE EMISION DE PLACA DE RODAJE
A45: 46088 | C45: 01 | D45: 00F003 | F45: 3719367 | G45: 6 | H45: 20101973922 | I45: =IF(H45="","",VLOOKUP(H45,ENTIDAD!$B$2:$C$613,2,0)) -> ASOCIACION AUTOMOTRIZ DEL PERU | N45: 0 | O45: =N45*0.18 -> 0 | P45: 0 | R45: 66.8 | S45: 66.8 | AB45: S | AD45: 46119 | AE45: CRE | AF45: 6599095 | AG45: 1413 | AH45: 4212 | AR45: 18 | AS45: POR DERECHO DE EMISION DE PLACA DE RODAJE
A46: 46088 | C46: 01 | D46: 00F003 | F46: 3719368 | G46: 6 | H46: 20101973922 | I46: =IF(H46="","",VLOOKUP(H46,ENTIDAD!$B$2:$C$613,2,0)) -> ASOCIACION AUTOMOTRIZ DEL PERU | N46: 0 | O46: =N46*0.18 -> 0 | P46: 0 | R46: 66.8 | S46: 66.8 | AB46: S | AD46: 46119 | AE46: CRE | AF46: 6599095 | AG46: 1413 | AH46: 4212 | AR46: 18 | AS46: POR DERECHO DE EMISION DE PLACA DE RODAJE
A47: 46088 | C47: 01 | D47: 00F003 | F47: 3719369 | G47: 6 | H47: 20101973922 | I47: =IF(H47="","",VLOOKUP(H47,ENTIDAD!$B$2:$C$613,2,0)) -> ASOCIACION AUTOMOTRIZ DEL PERU | N47: 0 | O47: =N47*0.18 -> 0 | P47: 0 | R47: 66.8 | S47: 66.8 | AB47: S | AD47: 46119 | AE47: CRE | AF47: 6599095 | AG47: 1413 | AH47: 4212 | AR47: 18 | AS47: POR DERECHO DE EMISION DE PLACA DE RODAJE
...

Sheet ABRIL
A1: FECHA DE EMISION DEL COMPROBANTE DE PAGO O DOCUMENTO | B1: FECHA DE VENCIMIENTO O FECHA DE PAGO | C1: COMPROBANTE DE PAGO O DOCUMENTO | F1: N° COMPROBANTE PAGO | G1: INFORMACION PROVEEDOR | J1: ADQUISICIONES GRAVADAS DESTINADAS A OPERACIONES GRAVADAS Y/O EXPORTACION | L1: ADQUISICIONES GRAVADAS DESTINADAS A OPERACIONES GRAVADAS Y/O DE EXPORTACION Y A OPERACIONES NO GRAVADAS | N1: ADQUISICIONES GRAVADAS DESTINADAS A OPERACIONES NO GRAVADAS | P1: VALOR DE LAS ADQUISICIONES NO GRAVADAS | Q1: ISC | R1: OTROS TRIBUTOS Y CARGOS | S1: IMPORTE TOTAL | T1: N° COMPROBANTE DE PAGO EMITIDO POR SUJETO NO DOMICILIADO | U1: CONSTANCIA DE DEPOSITO DE DETRACCION | W1: TIPO DE CAMBIO | X1: REFERENCIA DEL COMPROBANTE DE PAGO O DOCUMENTO ORIGINAL QUE SE MODIFICA | AB1: MONEDA | AC1: EQUIVALENTE EN DOLARES AMERICANOS | AD1: FECHA VENCIMIENTO | AE1: CONDICION CONTADO/CREDITO | AF1: CUENTA CONTABLE BASE IMPONIBLE | AG1: CUENTA CONTABLE OTROS TRIBUTOS Y CARGOS | AH1: CUENTA CONTABLE TOTAL | AI1: CODIGO CENTRO DE COSTOS | AJ1: CODIGO CENTRO DE COSTOS 2 | AK1: REGIMEN ESPECIAL | AL1: PORCENTAJE REGIMEN ESPECIAL | AM1: IMPORTE REGIMEN ESPECIAL | AN1: SERIE DOCUMENTO REGIMEN ESPECIAL | AO1: NUMERO DOCUMENTO REGIMEN ESPECIAL | AP1: FECHA DOCUMENTO REGIMEN ESPECIAL | AQ1: CODIGO PRESUPUESTO | AR1: PORCENTAJE I.G.V. | AS1: GLOSA | AT1: CONDICIÓN DE PERCEPCIÓN | AU1: IMPORTE RÉGIMEN ESPECIAL | AV1: CLASIFICACIÓN DE BIENES Y SERVICIOS ADQUIRIDOS
G2: DOCUMENTO IDENTIDAD | I2: APELLIDOS Y NOMBRES, DENOMINACION O RAZON SOCIAL
C3: TIPO | D3: SERIE/CODIGO ADUANA | E3: AÑO EMISION DUA O DSI | G3: TIPO | H3: NUMERO | J3: BASE IMPONIBLE | K3: IGV | L3: BASE IMPONIBLE | M3: IGV | N3: BASE IMPONIBLE | O3: IGV | U3: NUMERO | V3: FECHA EMISION | X3: FECHA | Y3: TIPO | Z3: SERIE | AA3: N° COMPROBANTE PAGO O DOCUMENTO
A4: 46101 | B4: 46120 | C4: 14 | D4: 00SB02 | F4: 275541604 | G4: 6 | H4: 20467534026 | I4: AMERICA MOVIL PERU S.A.C. | N4: 25.338983 | O4: 4.5610169 | P4: 0 | S4: 29.9 | AB4: S | AD4: 46131 | AE4: CRE | AF4: 6365095 | AH4: 4212 | AR4: 18 | AS4: SERVICIO DE TELEFONICA
A5: 46109 | B5: 46125 | C5: 14 | D5: 00S898 | F5: 5730536 | G5: 6 | H5: 20129646099 | I5: ELECTROCENTRO S.A. | N5: 0 | O5: 0 | P5: 435.2 | S5: 435.2 | AB5: S | AD5: 46125 | AE5: CRE | AF5: 6361095 | AH5: 4212 | AR5: 18 | AS5: SERVICIO DE ENERGIA ELECTRICA
A6: 46109 | B6: 46125 | C6: 14 | D6: 00S898 | F6: 5730541 | G6: 6 | H6: 20129646099 | I6: ELECTROCENTRO S.A. | N6: 0 | O6: 0 | P6: 99.6 | S6: 99.6 | AB6: S | AD6: 46125 | AE6: CRE | AF6: 6361095 | AH6: 4212 | AR6: 18 | AS6: SERVICIO DE ENERGIA ELECTRICA
A7: 46109 | B7: 46125 | C7: 14 | D7: 00S898 | F7: 5730759 | G7: 6 | H7: 20129646099 | I7: ELECTROCENTRO S.A. | N7: 0 | O7: 0 | P7: 584.4 | S7: 584.4 | AB7: S | AD7: 46125 | AE7: CRE | AF7: 6361095 | AH7: 4212 | AR7: 18 | AS7: SERVICIO DE ENERGIA ELECTRICA
A8: 46112 | B8: 46142 | C8: 14 | D8: 00S060 | F8: 1061880 | G8: 6 | H8: 20121876290 | I8: ENT.PREST.SERV.SANEAM.SELVA CENTRAL S.A | N8: 0 | O8: 0 | P8: 23.4 | S8: 23.4 | AB8: S | AD8: 46142 | AE8: CRE | AF8: 6363095 | AH8: 4212 | AR8: 18 | AS8: SERVICIO DE AGUA
A9: 46112 | B9: 46142 | C9: 14 | D9: 00S060 | F9: 1063470 | G9: 6 | H9: 20121876290 | I9: ENT.PREST.SERV.SANEAM.SELVA CENTRAL S.A | N9: 0 | O9: 0 | P9: 44.2 | S9: 44.2 | AB9: S | AD9: 46142 | AE9: CRE | AF9: 6363095 | AH9: 4212 | AR9: 18 | AS9: SERVICIO DE AGUA
A10: 46112 | B10: 46142 | C10: 14 | D10: 00S060 | F10: 1062629 | G10: 6 | H10: 20121876290 | I10: ENT.PREST.SERV.SANEAM.SELVA CENTRAL S.A | N10: 0 | O10: 0 | P10: 31.4 | S10: 31.4 | AB10: S | AD10: 46142 | AE10: CRE | AF10: 6363095 | AH10: 4212 | AR10: 18 | AS10: SERVICIO DE AGUA
A11: 46113 | B11: 46142 | C11: 01 | D11: 00F020 | F11: 19570 | G11: 6 | H11: 20485981536 | I11: EMPRESA DE TRANSPORTES TURISMO Y SERVICIOS MULTIPLES SHIMA E.I.R.L. | N11: 0 | O11: 0 | P11: 0 | R11: 40 | S11: 40 | AB11: S | AD11: 46142 | AE11: CRE | AF11: 6599095 | AG11: 1413 | AH11: 4212 | AR11: 18 | AS11: POR EL SERVICIO DE TRANSPORTE DE PASAJERO
A12: 46113 | C12: 01 | D12: 00E001 | F12: 1675 | G12: 6 | H12: 20611910887 | I12: CORPORACION UNIVERSAL M&F SOCIEDAD ANONIMA CERRADA | N12: 0 | O12: 0 | P12: 24 | S12: 24 | AB12: S | AE12: CON | AF12: 656009503 | AH12: 4212 | AR12: 18 | AS12: SELLO DE MADERA
A13: 46113 | B13: 46132 | C13: 14 | D13: 00SB01 | F13: 615581813 | G13: 6 | H13: 20467534026 | I13: AMERICA MOVIL PERU S.A.C. | N13: 75.177966 | O13: 13.532034 | P13: -0.02 | S13: 88.69 | AB13: S | AD13: 46132 | AE13: CRE | AF13: 6365095 | AH13: 4212 | AR13: 18 | AS13: SERVICIO DE INTERNET Y TELEFONIA
A14: 46113 | B14: 46143 | C14: 01 | D14: 00F003 | F14: 3768125 | G14: 6 | H14: 20101973922 | I14: ASOCIACION AUTOMOTRIZ DEL PERU | N14: 0 | O14: 0 | P14: 0 | R14: 66.8 | S14: 66.8 | AB14: S | AD14: 46143 | AE14: CRE | AF14: 6599095 | AG14: 1413 | AH14: 4212 | AR14: 18 | AS14: POR DERECHO DE EMISION DE PLACA DE RODAJE
A15: 46113 | B15: 46143 | C15: 01 | D15: 00F003 | F15: 3768124 | G15: 6 | H15: 20101973922 | I15: ASOCIACION AUTOMOTRIZ DEL PERU | N15: 0 | O15: 0 | P15: 0 | R15: 66.8 | S15: 66.8 | AB15: S | AD15: 46143 | AE15: CRE | AF15: 6599095 | AG15: 1413 | AH15: 4212 | AR15: 18 | AS15: POR DERECHO DE EMISION DE PLACA DE RODAJE
A16: 46113 | B16: 46143 | C16: 01 | D16: 00F003 | F16: 3768123 | G16: 6 | H16: 20101973922 | I16: ASOCIACION AUTOMOTRIZ DEL PERU | N16: 0 | O16: 0 | P16: 0 | R16: 66.8 | S16: 66.8 | AB16: S | AD16: 46143 | AE16: CRE | AF16: 6599095 | AG16: 1413 | AH16: 4212 | AR16: 18 | AS16: POR DERECHO DE EMISION DE PLACA DE RODAJE
A17: 46113 | B17: 46143 | C17: 01 | D17: 00F003 | F17: 3768122 | G17: 6 | H17: 20101973922 | I17: ASOCIACION AUTOMOTRIZ DEL PERU | N17: 0 | O17: 0 | P17: 0 | R17: 66.8 | S17: 66.8 | AB17: S | AD17: 46143 | AE17: CRE | AF17: 6599095 | AG17: 1413 | AH17: 4212 | AR17: 18 | AS17: POR DERECHO DE EMISION DE PLACA DE RODAJE
A18: 46113 | B18: 46143 | C18: 01 | D18: 00F003 | F18: 3768121 | G18: 6 | H18: 20101973922 | I18: ASOCIACION AUTOMOTRIZ DEL PERU | N18: 0 | O18: 0 | P18: 0 | R18: 66.8 | S18: 66.8 | AB18: S | AD18: 46143 | AE18: CRE | AF18: 6599095 | AG18: 1413 | AH18: 4212 | AR18: 18 | AS18: POR DERECHO DE EMISION DE PLACA DE RODAJE
A19: 46113 | B19: 46143 | C19: 01 | D19: 00F003 | F19: 3768120 | G19: 6 | H19: 20101973922 | I19: ASOCIACION AUTOMOTRIZ DEL PERU | N19: 0 | O19: 0 | P19: 0 | R19: 66.8 | S19: 66.8 | AB19: S | AD19: 46143 | AE19: CRE | AF19: 6599095 | AG19: 1413 | AH19: 4212 | AR19: 18 | AS19: POR DERECHO DE EMISION DE PLACA DE RODAJE
A20: 46113 | B20: 46143 | C20: 01 | D20: 00F003 | F20: 3768119 | G20: 6 | H20: 20101973922 | I20: ASOCIACION AUTOMOTRIZ DEL PERU | N20: 0 | O20: 0 | P20: 0 | R20: 66.8 | S20: 66.8 | AB20: S | AD20: 46143 | AE20: CRE | AF20: 6599095 | AG20: 1413 | AH20: 4212 | AR20: 18 | AS20: POR DERECHO DE EMISION DE PLACA DE RODAJE
A21: 46113 | B21: 46143 | C21: 01 | D21: 00F003 | F21: 3768118 | G21: 6 | H21: 20101973922 | I21: ASOCIACION AUTOMOTRIZ DEL PERU | N21: 0 | O21: 0 | P21: 0 | R21: 66.8 | S21: 66.8 | AB21: S | AD21: 46143 | AE21: CRE | AF21: 6599095 | AG21: 1413 | AH21: 4212 | AR21: 18 | AS21: POR DERECHO DE EMISION DE PLACA DE RODAJE
A22: 46113 | B22: 46143 | C22: 01 | D22: 00F003 | F22: 3768117 | G22: 6 | H22: 20101973922 | I22: ASOCIACION AUTOMOTRIZ DEL PERU | N22: 0 | O22: 0 | P22: 0 | R22: 66.8 | S22: 66.8 | AB22: S | AD22: 46143 | AE22: CRE | AF22: 6599095 | AG22: 1413 | AH22: 4212 | AR22: 18 | AS22: POR DERECHO DE EMISION DE PLACA DE RODAJE
A23: 46113 | B23: 46143 | C23: 01 | D23: 00F003 | F23: 3768116 | G23: 6 | H23: 20101973922 | I23: ASOCIACION AUTOMOTRIZ DEL PERU | N23: 0 | O23: 0 | P23: 0 | R23: 66.8 | S23: 66.8 | AB23: S | AD23: 46143 | AE23: CRE | AF23: 6599095 | AG23: 1413 | AH23: 4212 | AR23: 18 | AS23: POR DERECHO DE EMISION DE PLACA DE RODAJE
A24: 46113 | B24: 46143 | C24: 01 | D24: 00F003 | F24: 3768115 | G24: 6 | H24: 20101973922 | I24: ASOCIACION AUTOMOTRIZ DEL PERU | N24: 0 | O24: 0 | P24: 0 | R24: 66.8 | S24: 66.8 | AB24: S | AD24: 46143 | AE24: CRE | AF24: 6599095 | AG24: 1413 | AH24: 4212 | AR24: 18 | AS24: POR DERECHO DE EMISION DE PLACA DE RODAJE
A25: 46113 | B25: 46143 | C25: 01 | D25: 00F003 | F25: 3768114 | G25: 6 | H25: 20101973922 | I25: ASOCIACION AUTOMOTRIZ DEL PERU | N25: 0 | O25: 0 | P25: 0 | R25: 66.8 | S25: 66.8 | AB25: S | AD25: 46143 | AE25: CRE | AF25: 6599095 | AG25: 1413 | AH25: 4212 | AR25: 18 | AS25: POR DERECHO DE EMISION DE PLACA DE RODAJE
... A34: 46113 | B34: 46143 | C34: 01 | D34: 00F003 | F34: 3768104 | G34: 6 | H34: 20101973922 | I34: ASOCIACION AUTOMOTRIZ DEL PERU | N34: 0 | O34: 0 | P34: 0 | R34: 66.8 | S34: 66.8 | AB34: S | AD34: 46143 | AE34: CRE | AF34: 6599095 | AG34: 1413 | AH34: 4212 | AR34: 18 | AS34: POR DERECHO DE EMISION DE PLACA DE RODAJE
A35: 46113 | C35: 01 | D35: 00F001 | F35: 12661 | G35: 6 | H35: 10209907327 | I35: TORPOCO,MAYTA,HECTOR,ALFONSO | N35: 0 | O35: 0 | P35: 10 | S35: 10 | AB35: S | AE35: CON | AF35: 656009501 | AH35: 4212 | AR35: 18 | AS35: POR LA COMPRA DE COMBUSTIBLE
A36: 46113 | B36: 46143 | C36: 01 | D36: 00F003 | F36: 3768113 | G36: 6 | H36: 20101973922 | I36: ASOCIACION AUTOMOTRIZ DEL PERU | N36: 56.610169 | O36: 10.189831 | P36: 0 | S36: 66.8 | AB36: S | AD36: 46143 | AE36: CRE | AF36: 6599095 | AG36: 1413 | AH36: 4212 | AR36: 18 | AS36: POR DERECHO DE EMISION DE PLACA DE RODAJE
A37: 46114 | C37: 01 | D37: 00F001 | F37: 118669 | G37: 6 | H37: 20568499043 | I37: SURTIDORES SAN MIGUEL E.I.R.L. | N37: 0 | O37: 0 | P37: 100 | S37: 100 | AB37: S | AE37: CON | AF37: 656009501 | AH37: 4212 | AR37: 18 | AS37: POR LA COMPRA DE COMBUSTIBLE
A38: 46116 | B38: 46146 | C38: 01 | D38: 00F010 | F38: 4817 | G38: 6 | H38: 20601012261 | I38: IMPORTADORA DE REPUESTOS LA ROCA E.I.R.L. | N38: 0 | O38: 0 | P38: 14 | S38: 14 | AB38: S | AD38: 46146 | AE38: CON | AF38: 656009507 | AH38: 4212 | AR38: 18 | AS38: SWITCH UNIVERSAL C/BASE P/TIMON 3C NG YANGZU D003022
A39: 46118 | B39: 46148 | C39: 01 | D39: 00FC04 | F39: 4964259 | G39: 6 | H39: 20100130204 | I39: BANCO BBVA PERU | N39: 0 | O39: 0 | P39: 40 | S39: 40 | AB39: S | AD39: 46148 | AE39: CRE | AF39: 6391094 | AH39: 4212 | AR39: 18 | AS39: POR LA COMISION BANCARIA
A40: 46118 | B40: 46148 | C40: 01 | D40: 00FB26 | F40: 26742968 | G40: 6 | H40: 20100130204 | I40: BANCO BBVA PERU | N40: 0 | O40: 0 | P40: 10 | S40: 10 | AB40: S | AD40: 46148 | AE40: CRE | AF40: 6391094 | AH40: 4212 | AR40: 18 | AS40: POR LA COMISION BANCARIA
A41: 46118 | C41: 01 | D41: 00F001 | F41: 118745 | G41: 6 | H41: 20568499043 | I41: SURTIDORES SAN MIGUEL E.I.R.L. | N41: 0 | O41: 0 | P41: 113.5 | S41: 113.5 | AB41: S | AE41: CON | AF41: 656009501 | AH41: 4212 | AR41: 18 | AS41: POR LA COMPRA DE COMBUSTIBLE
A42: 46119 | B42: 46149 | C42: 01 | D42: 00E001 | F42: 197 | G42: 6 | H42: 10447422951 | I42: ZEGARRA AZAÑERO JORGE KEY | N42: 0 | O42: 0 | P42: 450 | S42: 450 | AB42: S | AD42: 46149 | AE42: CRE | AF42: 6329094 | AH42: 4212 | AR42: 18 | AS42: SOPORTE TECNICO
A43: 46119 | B43: 46149 | C43: 01 | D43: 00E001 | F43: 3 | G43: 6 | H43: 20615490548 | I43: CORPORACION TOSCANO TECNOLOGY PERÚ SOCIEDAD ANONIMA CERRADA | N43: 0 | O43: 0 | P43: 270 | S43: 270 | AB43: S | AD43: 46149 | AE43: CRE | AF43: 6011020 | AH43: 4212 | AR43: 18 | AS43: PARABRIZA ESCHIZO TRIANGULO
A44: 46119 | B44: 46149 | C44: 01 | D44: 00F010 | F44: 4831 | G44: 6 | H44: 20601012261 | I44: IMPORTADORA DE REPUESTOS LA ROCA E.I.R.L. | N44: 0 | O44: 0 | P44: 3.5 | S44: 3.5 | AB44: S | AD44: 46149 | AE44: CRE | AF44: 656009507 | AH44: 4212 | AR44: 18 | AS44: PORTA FUSIBLE , FUSIBLE
A45: 46120 | B45: 46150 | C45: 01 | D45: 00FB26 | F45: 26812174 | G45: 6 | H45: 20100130204 | I45: BANCO BBVA PERU | N45: 0 | O45: 0 | P45: 7.91 | S45: 7.91 | AB45: S | AD45: 46150 | AE45: CRE | AF45: 6391094 | AH45: 4212 | AR45: 18 | AS45: POR LA COMISION BANCARIA
A46: 46120 | B46: 46150 | C46: 01 | D46: 00FE01 | F46: 2804050 | G46: 6 | H46: 20100047218 | I46: BANCO DE CREDITO DEL PERU | N46: 1.2043097e-14 | O46: 2.1677575e-15 | P46: 120.33 | S46: 120.33 | W46: 3.438 | AB46: D | AC46: 35 | AD46: 46150 | AE46: CRE | AF46: 6391094 | AH46: 4212 | AR46: 18 | AS46: POR COMISION DE TELECREDITO
A47: 46120 | B47: 46150 | C47: 01 | D47: 00F002 | F47: 140 | G47: 6 | H47: 20600454065 | I47: REPUESTOS Y SERVICIOS ARAUCO E.I.R.L. | N47: 0 | O47: 0 | P47: 2075 | S47: 2075 | AB47: S | AD47: 46150 | AE47: CRE | AF47: 6343095 | AH47: 4212 | AR47: 18 | AS47: MANTENIMIENTO DE MOTOS VENDIDAS - GARANTIA
A48: 46121 | B48: 46151 | C48: 01 | D48: 00FV12 | F48: 1345247 | G48: 6 | H48: 20100047218 | I48: BANCO DE CREDITO DEL PERU | N48: 0 | O48: 0 | P48: 138 | S48: 138 | AB48: S | AD48: 46151 | AE48: CRE | AF48: 6391094 | AH48: 4212 | AR48: 18 | AS48: POR MANTENIMIENTO,OPER.EXCESO,APORTE Y ESTADO
...

Sheet MAYO
A1: FECHA DE EMISION DEL COMPROBANTE DE PAGO O DOCUMENTO | B1: FECHA DE VENCIMIENTO O FECHA DE PAGO | C1: COMPROBANTE DE PAGO O DOCUMENTO | F1: N° COMPROBANTE PAGO | G1: INFORMACION PROVEEDOR | J1: ADQUISICIONES GRAVADAS DESTINADAS A OPERACIONES GRAVADAS Y/O EXPORTACION | L1: ADQUISICIONES GRAVADAS DESTINADAS A OPERACIONES GRAVADAS Y/O DE EXPORTACION Y A OPERACIONES NO GRAVADAS | N1: ADQUISICIONES GRAVADAS DESTINADAS A OPERACIONES NO GRAVADAS | P1: VALOR DE LAS ADQUISICIONES NO GRAVADAS | Q1: ISC | R1: OTROS TRIBUTOS Y CARGOS | S1: IMPORTE TOTAL | T1: N° COMPROBANTE DE PAGO EMITIDO POR SUJETO NO DOMICILIADO | U1: CONSTANCIA DE DEPOSITO DE DETRACCION | W1: TIPO DE CAMBIO | X1: REFERENCIA DEL COMPROBANTE DE PAGO O DOCUMENTO ORIGINAL QUE SE MODIFICA | AB1: MONEDA | AC1: EQUIVALENTE EN DOLARES AMERICANOS | AD1: FECHA VENCIMIENTO | AE1: CONDICION CONTADO/CREDITO | AF1: CUENTA CONTABLE BASE IMPONIBLE | AG1: CUENTA CONTABLE OTROS TRIBUTOS Y CARGOS | AH1: CUENTA CONTABLE TOTAL | AI1: CODIGO CENTRO DE COSTOS | AJ1: CODIGO CENTRO DE COSTOS 2 | AK1: REGIMEN ESPECIAL | AL1: PORCENTAJE REGIMEN ESPECIAL | AM1: IMPORTE REGIMEN ESPECIAL | AN1: SERIE DOCUMENTO REGIMEN ESPECIAL | AO1: NUMERO DOCUMENTO REGIMEN ESPECIAL | AP1: FECHA DOCUMENTO REGIMEN ESPECIAL | AQ1: CODIGO PRESUPUESTO | AR1: PORCENTAJE I.G.V. | AS1: GLOSA | AT1: CONDICIÓN DE PERCEPCIÓN | AU1: IMPORTE RÉGIMEN ESPECIAL | AV1: CLASIFICACIÓN DE BIENES Y SERVICIOS ADQUIRIDOS
G2: DOCUMENTO IDENTIDAD | I2: APELLIDOS Y NOMBRES, DENOMINACION O RAZON SOCIAL
C3: TIPO | D3: SERIE/CODIGO ADUANA | E3: AÑO EMISION DUA O DSI | G3: TIPO | H3: NUMERO | J3: BASE IMPONIBLE | K3: IGV | L3: BASE IMPONIBLE | M3: IGV | N3: BASE IMPONIBLE | O3: IGV | U3: NUMERO | V3: FECHA EMISION | X3: FECHA | Y3: TIPO | Z3: SERIE | AA3: N° COMPROBANTE PAGO O DOCUMENTO
